 
aes256 1KB upload test 1 :
OK

real	0m0.273s
user	0m0.122s
sys	0m0.064s
 
aes256 1KB upload test 2 :
OK

real	0m0.124s
user	0m0.094s
sys	0m0.023s
 
aes256 1KB upload test 3 :
OK

real	0m0.139s
user	0m0.106s
sys	0m0.026s
 
aes256 1KB upload test 4 :
OK

real	0m0.133s
user	0m0.103s
sys	0m0.025s
 
aes256 1KB upload test 5 :
OK

real	0m0.125s
user	0m0.096s
sys	0m0.023s
 
aes256 1KB upload test 6 :
OK

real	0m0.129s
user	0m0.099s
sys	0m0.024s
 
aes256 1KB upload test 7 :
OK

real	0m0.139s
user	0m0.107s
sys	0m0.026s
 
aes256 1KB upload test 8 :
OK

real	0m0.128s
user	0m0.098s
sys	0m0.023s
 
aes256 1KB upload test 9 :
OK

real	0m0.126s
user	0m0.097s
sys	0m0.023s
 
aes256 1KB upload test 10 :
OK

real	0m0.125s
user	0m0.095s
sys	0m0.023s
 
aes256 1MB upload test 1 :
OK

real	0m8.783s
user	0m7.990s
sys	0m0.759s
 
aes256 1MB upload test 2 :
OK

real	0m8.108s
user	0m7.466s
sys	0m0.664s
 
aes256 1MB upload test 3 :
OK

real	0m8.356s
user	0m7.641s
sys	0m0.725s
 
aes256 1MB upload test 4 :
OK

real	0m8.113s
user	0m7.475s
sys	0m0.662s
 
aes256 1MB upload test 5 :
OK

real	0m8.124s
user	0m7.471s
sys	0m0.674s
 
aes256 1MB upload test 6 :
OK

real	0m8.267s
user	0m7.637s
sys	0m0.652s
 
aes256 1MB upload test 7 :
OK

real	0m8.129s
user	0m7.494s
sys	0m0.658s
 
aes256 1MB upload test 8 :
OK

real	0m8.220s
user	0m7.592s
sys	0m0.651s
 
aes256 1MB upload test 9 :
OK

real	0m8.142s
user	0m7.506s
sys	0m0.658s
 
aes256 1MB upload test 10 :
OK

real	0m8.118s
user	0m7.484s
sys	0m0.657s
 
aes256 1GB upload test 1 :
Traceback (most recent call last):
  File "FTclient.py", line 189, in <module>
    main()
  File "FTclient.py", line 176, in main
    upload(server_socket)
  File "FTclient.py", line 57, in upload
    sendData(conn, block)                                               # Encrypt then send the remainder of block
  File "FTclient.py", line 73, in sendData
    conn.sendall(encrypted_bytes)
  File "/usr/local/Cellar/python/2.7.13/Frameworks/Python.framework/Versions/2.7/lib/python2.7/socket.py", line 228, in meth
    return getattr(self._sock,name)(*args)
socket.error: [Errno 41] Protocol wrong type for socket

real	0m9.283s
user	0m4.607s
sys	0m3.570s
 
aes256 1GB upload test 2 :
Traceback (most recent call last):
  File "FTclient.py", line 189, in <module>
    main()
  File "FTclient.py", line 164, in main
    server_socket.connect((HOST, PORT))
  File "/usr/local/Cellar/python/2.7.13/Frameworks/Python.framework/Versions/2.7/lib/python2.7/socket.py", line 228, in meth
    return getattr(self._sock,name)(*args)
socket.error: [Errno 61] Connection refused

real	0m0.080s
user	0m0.043s
sys	0m0.019s
 
aes256 1GB upload test 3 :
Traceback (most recent call last):
  File "FTclient.py", line 189, in <module>
    main()
  File "FTclient.py", line 164, in main
    server_socket.connect((HOST, PORT))
  File "/usr/local/Cellar/python/2.7.13/Frameworks/Python.framework/Versions/2.7/lib/python2.7/socket.py", line 228, in meth
    return getattr(self._sock,name)(*args)
socket.error: [Errno 61] Connection refused

real	0m0.051s
user	0m0.036s
sys	0m0.013s
 
aes256 1GB upload test 4 :
Traceback (most recent call last):
  File "FTclient.py", line 189, in <module>
    main()
  File "FTclient.py", line 164, in main
    server_socket.connect((HOST, PORT))
  File "/usr/local/Cellar/python/2.7.13/Frameworks/Python.framework/Versions/2.7/lib/python2.7/socket.py", line 228, in meth
    return getattr(self._sock,name)(*args)
socket.error: [Errno 61] Connection refused

real	0m0.052s
user	0m0.037s
sys	0m0.013s
 
aes256 1GB upload test 5 :
Traceback (most recent call last):
  File "FTclient.py", line 189, in <module>
    main()
  File "FTclient.py", line 164, in main
    server_socket.connect((HOST, PORT))
  File "/usr/local/Cellar/python/2.7.13/Frameworks/Python.framework/Versions/2.7/lib/python2.7/socket.py", line 228, in meth
    return getattr(self._sock,name)(*args)
socket.error: [Errno 61] Connection refused

real	0m0.052s
user	0m0.037s
sys	0m0.013s
 
aes256 1GB upload test 6 :
Traceback (most recent call last):
  File "FTclient.py", line 189, in <module>
    main()
  File "FTclient.py", line 164, in main
    server_socket.connect((HOST, PORT))
  File "/usr/local/Cellar/python/2.7.13/Frameworks/Python.framework/Versions/2.7/lib/python2.7/socket.py", line 228, in meth
    return getattr(self._sock,name)(*args)
socket.error: [Errno 61] Connection refused

real	0m0.055s
user	0m0.039s
sys	0m0.014s
 
aes256 1GB upload test 7 :
Traceback (most recent call last):
  File "FTclient.py", line 189, in <module>
    main()
  File "FTclient.py", line 164, in main
    server_socket.connect((HOST, PORT))
  File "/usr/local/Cellar/python/2.7.13/Frameworks/Python.framework/Versions/2.7/lib/python2.7/socket.py", line 228, in meth
    return getattr(self._sock,name)(*args)
socket.error: [Errno 61] Connection refused

real	0m0.052s
user	0m0.036s
sys	0m0.014s
 
aes256 1GB upload test 8 :
Traceback (most recent call last):
  File "FTclient.py", line 189, in <module>
    main()
  File "FTclient.py", line 164, in main
    server_socket.connect((HOST, PORT))
  File "/usr/local/Cellar/python/2.7.13/Frameworks/Python.framework/Versions/2.7/lib/python2.7/socket.py", line 228, in meth
    return getattr(self._sock,name)(*args)
socket.error: [Errno 61] Connection refused

real	0m0.053s
user	0m0.037s
sys	0m0.013s
 
aes256 1GB upload test 9 :
Traceback (most recent call last):
  File "FTclient.py", line 189, in <module>
    main()
  File "FTclient.py", line 164, in main
    server_socket.connect((HOST, PORT))
  File "/usr/local/Cellar/python/2.7.13/Frameworks/Python.framework/Versions/2.7/lib/python2.7/socket.py", line 228, in meth
    return getattr(self._sock,name)(*args)
socket.error: [Errno 61] Connection refused

real	0m0.052s
user	0m0.036s
sys	0m0.013s
 
aes256 1GB upload test 10 :
Traceback (most recent call last):
  File "FTclient.py", line 189, in <module>
    main()
  File "FTclient.py", line 164, in main
    server_socket.connect((HOST, PORT))
  File "/usr/local/Cellar/python/2.7.13/Frameworks/Python.framework/Versions/2.7/lib/python2.7/socket.py", line 228, in meth
    return getattr(self._sock,name)(*args)
socket.error: [Errno 61] Connection refused

real	0m0.058s
user	0m0.041s
sys	0m0.015s
 
aes128 1KB upload test 1 :
Traceback (most recent call last):
  File "FTclient.py", line 189, in <module>
    main()
  File "FTclient.py", line 164, in main
    server_socket.connect((HOST, PORT))
  File "/usr/local/Cellar/python/2.7.13/Frameworks/Python.framework/Versions/2.7/lib/python2.7/socket.py", line 228, in meth
    return getattr(self._sock,name)(*args)
socket.error: [Errno 61] Connection refused

real	0m0.055s
user	0m0.039s
sys	0m0.013s
 
aes128 1KB upload test 2 :
Traceback (most recent call last):
  File "FTclient.py", line 189, in <module>
    main()
  File "FTclient.py", line 164, in main
    server_socket.connect((HOST, PORT))
  File "/usr/local/Cellar/python/2.7.13/Frameworks/Python.framework/Versions/2.7/lib/python2.7/socket.py", line 228, in meth
    return getattr(self._sock,name)(*args)
socket.error: [Errno 61] Connection refused

real	0m0.052s
user	0m0.037s
sys	0m0.012s
 
aes128 1KB upload test 3 :
Traceback (most recent call last):
  File "FTclient.py", line 189, in <module>
    main()
  File "FTclient.py", line 164, in main
    server_socket.connect((HOST, PORT))
  File "/usr/local/Cellar/python/2.7.13/Frameworks/Python.framework/Versions/2.7/lib/python2.7/socket.py", line 228, in meth
    return getattr(self._sock,name)(*args)
socket.error: [Errno 61] Connection refused

real	0m0.052s
user	0m0.037s
sys	0m0.012s
 
aes128 1KB upload test 4 :
Traceback (most recent call last):
  File "FTclient.py", line 189, in <module>
    main()
  File "FTclient.py", line 164, in main
    server_socket.connect((HOST, PORT))
  File "/usr/local/Cellar/python/2.7.13/Frameworks/Python.framework/Versions/2.7/lib/python2.7/socket.py", line 228, in meth
    return getattr(self._sock,name)(*args)
socket.error: [Errno 61] Connection refused

real	0m0.052s
user	0m0.037s
sys	0m0.012s
 
aes128 1KB upload test 5 :
Traceback (most recent call last):
  File "FTclient.py", line 189, in <module>
    main()
  File "FTclient.py", line 164, in main
    server_socket.connect((HOST, PORT))
  File "/usr/local/Cellar/python/2.7.13/Frameworks/Python.framework/Versions/2.7/lib/python2.7/socket.py", line 228, in meth
    return getattr(self._sock,name)(*args)
socket.error: [Errno 61] Connection refused

real	0m0.054s
user	0m0.038s
sys	0m0.013s
 
aes128 1KB upload test 6 :
Traceback (most recent call last):
  File "FTclient.py", line 189, in <module>
    main()
  File "FTclient.py", line 164, in main
    server_socket.connect((HOST, PORT))
  File "/usr/local/Cellar/python/2.7.13/Frameworks/Python.framework/Versions/2.7/lib/python2.7/socket.py", line 228, in meth
    return getattr(self._sock,name)(*args)
socket.error: [Errno 61] Connection refused

real	0m0.052s
user	0m0.037s
sys	0m0.012s
 
aes128 1KB upload test 7 :
Traceback (most recent call last):
  File "FTclient.py", line 189, in <module>
    main()
  File "FTclient.py", line 164, in main
    server_socket.connect((HOST, PORT))
  File "/usr/local/Cellar/python/2.7.13/Frameworks/Python.framework/Versions/2.7/lib/python2.7/socket.py", line 228, in meth
    return getattr(self._sock,name)(*args)
socket.error: [Errno 61] Connection refused

real	0m0.052s
user	0m0.037s
sys	0m0.012s
 
aes128 1KB upload test 8 :
Traceback (most recent call last):
  File "FTclient.py", line 189, in <module>
    main()
  File "FTclient.py", line 164, in main
    server_socket.connect((HOST, PORT))
  File "/usr/local/Cellar/python/2.7.13/Frameworks/Python.framework/Versions/2.7/lib/python2.7/socket.py", line 228, in meth
    return getattr(self._sock,name)(*args)
socket.error: [Errno 61] Connection refused

real	0m0.053s
user	0m0.037s
sys	0m0.013s
 
aes128 1KB upload test 9 :
Traceback (most recent call last):
  File "FTclient.py", line 189, in <module>
    main()
  File "FTclient.py", line 164, in main
    server_socket.connect((HOST, PORT))
  File "/usr/local/Cellar/python/2.7.13/Frameworks/Python.framework/Versions/2.7/lib/python2.7/socket.py", line 228, in meth
    return getattr(self._sock,name)(*args)
socket.error: [Errno 61] Connection refused

real	0m0.051s
user	0m0.037s
sys	0m0.012s
 
aes128 1KB upload test 10 :
Traceback (most recent call last):
  File "FTclient.py", line 189, in <module>
    main()
  File "FTclient.py", line 164, in main
    server_socket.connect((HOST, PORT))
  File "/usr/local/Cellar/python/2.7.13/Frameworks/Python.framework/Versions/2.7/lib/python2.7/socket.py", line 228, in meth
    return getattr(self._sock,name)(*args)
socket.error: [Errno 61] Connection refused

real	0m0.052s
user	0m0.037s
sys	0m0.012s
 
aes128 1MB upload test 1 :
Traceback (most recent call last):
  File "FTclient.py", line 189, in <module>
    main()
  File "FTclient.py", line 164, in main
    server_socket.connect((HOST, PORT))
  File "/usr/local/Cellar/python/2.7.13/Frameworks/Python.framework/Versions/2.7/lib/python2.7/socket.py", line 228, in meth
    return getattr(self._sock,name)(*args)
socket.error: [Errno 61] Connection refused

real	0m0.052s
user	0m0.037s
sys	0m0.013s
 
aes128 1MB upload test 2 :
Traceback (most recent call last):
  File "FTclient.py", line 189, in <module>
    main()
  File "FTclient.py", line 164, in main
    server_socket.connect((HOST, PORT))
  File "/usr/local/Cellar/python/2.7.13/Frameworks/Python.framework/Versions/2.7/lib/python2.7/socket.py", line 228, in meth
    return getattr(self._sock,name)(*args)
socket.error: [Errno 61] Connection refused

real	0m0.052s
user	0m0.037s
sys	0m0.013s
 
aes128 1MB upload test 3 :
Traceback (most recent call last):
  File "FTclient.py", line 189, in <module>
    main()
  File "FTclient.py", line 164, in main
    server_socket.connect((HOST, PORT))
  File "/usr/local/Cellar/python/2.7.13/Frameworks/Python.framework/Versions/2.7/lib/python2.7/socket.py", line 228, in meth
    return getattr(self._sock,name)(*args)
socket.error: [Errno 61] Connection refused

real	0m0.053s
user	0m0.037s
sys	0m0.013s
 
aes128 1MB upload test 4 :
Traceback (most recent call last):
  File "FTclient.py", line 189, in <module>
    main()
  File "FTclient.py", line 164, in main
    server_socket.connect((HOST, PORT))
  File "/usr/local/Cellar/python/2.7.13/Frameworks/Python.framework/Versions/2.7/lib/python2.7/socket.py", line 228, in meth
    return getattr(self._sock,name)(*args)
socket.error: [Errno 61] Connection refused

real	0m0.056s
user	0m0.040s
sys	0m0.015s
 
aes128 1MB upload test 5 :
Traceback (most recent call last):
  File "FTclient.py", line 189, in <module>
    main()
  File "FTclient.py", line 164, in main
    server_socket.connect((HOST, PORT))
  File "/usr/local/Cellar/python/2.7.13/Frameworks/Python.framework/Versions/2.7/lib/python2.7/socket.py", line 228, in meth
    return getattr(self._sock,name)(*args)
socket.error: [Errno 61] Connection refused

real	0m0.053s
user	0m0.037s
sys	0m0.013s
 
aes128 1MB upload test 6 :
Traceback (most recent call last):
  File "FTclient.py", line 189, in <module>
    main()
  File "FTclient.py", line 164, in main
    server_socket.connect((HOST, PORT))
  File "/usr/local/Cellar/python/2.7.13/Frameworks/Python.framework/Versions/2.7/lib/python2.7/socket.py", line 228, in meth
    return getattr(self._sock,name)(*args)
socket.error: [Errno 61] Connection refused

real	0m0.056s
user	0m0.040s
sys	0m0.015s
 
aes128 1MB upload test 7 :
Traceback (most recent call last):
  File "FTclient.py", line 189, in <module>
    main()
  File "FTclient.py", line 164, in main
    server_socket.connect((HOST, PORT))
  File "/usr/local/Cellar/python/2.7.13/Frameworks/Python.framework/Versions/2.7/lib/python2.7/socket.py", line 228, in meth
    return getattr(self._sock,name)(*args)
socket.error: [Errno 61] Connection refused

real	0m0.052s
user	0m0.037s
sys	0m0.013s
 
aes128 1MB upload test 8 :
Traceback (most recent call last):
  File "FTclient.py", line 189, in <module>
    main()
  File "FTclient.py", line 164, in main
    server_socket.connect((HOST, PORT))
  File "/usr/local/Cellar/python/2.7.13/Frameworks/Python.framework/Versions/2.7/lib/python2.7/socket.py", line 228, in meth
    return getattr(self._sock,name)(*args)
socket.error: [Errno 61] Connection refused

real	0m0.052s
user	0m0.037s
sys	0m0.013s
 
aes128 1MB upload test 9 :
Traceback (most recent call last):
  File "FTclient.py", line 189, in <module>
    main()
  File "FTclient.py", line 164, in main
    server_socket.connect((HOST, PORT))
  File "/usr/local/Cellar/python/2.7.13/Frameworks/Python.framework/Versions/2.7/lib/python2.7/socket.py", line 228, in meth
    return getattr(self._sock,name)(*args)
socket.error: [Errno 61] Connection refused

real	0m0.053s
user	0m0.038s
sys	0m0.014s
 
aes128 1MB upload test 10 :
Traceback (most recent call last):
  File "FTclient.py", line 189, in <module>
    main()
  File "FTclient.py", line 164, in main
    server_socket.connect((HOST, PORT))
  File "/usr/local/Cellar/python/2.7.13/Frameworks/Python.framework/Versions/2.7/lib/python2.7/socket.py", line 228, in meth
    return getattr(self._sock,name)(*args)
socket.error: [Errno 61] Connection refused

real	0m0.053s
user	0m0.038s
sys	0m0.014s
 
aes128 1GB upload test 1 :
Traceback (most recent call last):
  File "FTclient.py", line 189, in <module>
    main()
  File "FTclient.py", line 164, in main
    server_socket.connect((HOST, PORT))
  File "/usr/local/Cellar/python/2.7.13/Frameworks/Python.framework/Versions/2.7/lib/python2.7/socket.py", line 228, in meth
    return getattr(self._sock,name)(*args)
socket.error: [Errno 61] Connection refused

real	0m0.051s
user	0m0.037s
sys	0m0.013s
 
aes128 1GB upload test 2 :
Traceback (most recent call last):
  File "FTclient.py", line 189, in <module>
    main()
  File "FTclient.py", line 164, in main
    server_socket.connect((HOST, PORT))
  File "/usr/local/Cellar/python/2.7.13/Frameworks/Python.framework/Versions/2.7/lib/python2.7/socket.py", line 228, in meth
    return getattr(self._sock,name)(*args)
socket.error: [Errno 61] Connection refused

real	0m0.052s
user	0m0.037s
sys	0m0.013s
 
aes128 1GB upload test 3 :
Traceback (most recent call last):
  File "FTclient.py", line 189, in <module>
    main()
  File "FTclient.py", line 164, in main
    server_socket.connect((HOST, PORT))
  File "/usr/local/Cellar/python/2.7.13/Frameworks/Python.framework/Versions/2.7/lib/python2.7/socket.py", line 228, in meth
    return getattr(self._sock,name)(*args)
socket.error: [Errno 61] Connection refused

real	0m0.052s
user	0m0.037s
sys	0m0.013s
 
aes128 1GB upload test 4 :
Traceback (most recent call last):
  File "FTclient.py", line 189, in <module>
    main()
  File "FTclient.py", line 164, in main
    server_socket.connect((HOST, PORT))
  File "/usr/local/Cellar/python/2.7.13/Frameworks/Python.framework/Versions/2.7/lib/python2.7/socket.py", line 228, in meth
    return getattr(self._sock,name)(*args)
socket.error: [Errno 61] Connection refused

real	0m0.052s
user	0m0.038s
sys	0m0.013s
 
aes128 1GB upload test 5 :
Traceback (most recent call last):
  File "FTclient.py", line 189, in <module>
    main()
  File "FTclient.py", line 164, in main
    server_socket.connect((HOST, PORT))
  File "/usr/local/Cellar/python/2.7.13/Frameworks/Python.framework/Versions/2.7/lib/python2.7/socket.py", line 228, in meth
    return getattr(self._sock,name)(*args)
socket.error: [Errno 61] Connection refused

real	0m0.053s
user	0m0.037s
sys	0m0.013s
 
aes128 1GB upload test 6 :
Traceback (most recent call last):
  File "FTclient.py", line 189, in <module>
    main()
  File "FTclient.py", line 164, in main
    server_socket.connect((HOST, PORT))
  File "/usr/local/Cellar/python/2.7.13/Frameworks/Python.framework/Versions/2.7/lib/python2.7/socket.py", line 228, in meth
    return getattr(self._sock,name)(*args)
socket.error: [Errno 61] Connection refused

real	0m0.053s
user	0m0.037s
sys	0m0.013s
 
aes128 1GB upload test 7 :
Traceback (most recent call last):
  File "FTclient.py", line 189, in <module>
    main()
  File "FTclient.py", line 164, in main
    server_socket.connect((HOST, PORT))
  File "/usr/local/Cellar/python/2.7.13/Frameworks/Python.framework/Versions/2.7/lib/python2.7/socket.py", line 228, in meth
    return getattr(self._sock,name)(*args)
socket.error: [Errno 61] Connection refused

real	0m0.052s
user	0m0.037s
sys	0m0.013s
 
aes128 1GB upload test 8 :
Traceback (most recent call last):
  File "FTclient.py", line 189, in <module>
    main()
  File "FTclient.py", line 164, in main
    server_socket.connect((HOST, PORT))
  File "/usr/local/Cellar/python/2.7.13/Frameworks/Python.framework/Versions/2.7/lib/python2.7/socket.py", line 228, in meth
    return getattr(self._sock,name)(*args)
socket.error: [Errno 61] Connection refused

real	0m0.056s
user	0m0.041s
sys	0m0.014s
 
aes128 1GB upload test 9 :
Traceback (most recent call last):
  File "FTclient.py", line 189, in <module>
    main()
  File "FTclient.py", line 164, in main
    server_socket.connect((HOST, PORT))
  File "/usr/local/Cellar/python/2.7.13/Frameworks/Python.framework/Versions/2.7/lib/python2.7/socket.py", line 228, in meth
    return getattr(self._sock,name)(*args)
socket.error: [Errno 61] Connection refused

real	0m0.053s
user	0m0.038s
sys	0m0.014s
 
aes128 1GB upload test 10 :
Traceback (most recent call last):
  File "FTclient.py", line 189, in <module>
    main()
  File "FTclient.py", line 164, in main
    server_socket.connect((HOST, PORT))
  File "/usr/local/Cellar/python/2.7.13/Frameworks/Python.framework/Versions/2.7/lib/python2.7/socket.py", line 228, in meth
    return getattr(self._sock,name)(*args)
socket.error: [Errno 61] Connection refused

real	0m0.051s
user	0m0.037s
sys	0m0.013s
 
null 1KB upload test 1 :
Traceback (most recent call last):
  File "FTclient.py", line 189, in <module>
    main()
  File "FTclient.py", line 164, in main
    server_socket.connect((HOST, PORT))
  File "/usr/local/Cellar/python/2.7.13/Frameworks/Python.framework/Versions/2.7/lib/python2.7/socket.py", line 228, in meth
    return getattr(self._sock,name)(*args)
socket.error: [Errno 61] Connection refused

real	0m0.052s
user	0m0.037s
sys	0m0.012s
 
null 1KB upload test 2 :
Traceback (most recent call last):
  File "FTclient.py", line 189, in <module>
    main()
  File "FTclient.py", line 164, in main
    server_socket.connect((HOST, PORT))
  File "/usr/local/Cellar/python/2.7.13/Frameworks/Python.framework/Versions/2.7/lib/python2.7/socket.py", line 228, in meth
    return getattr(self._sock,name)(*args)
socket.error: [Errno 61] Connection refused

real	0m0.053s
user	0m0.037s
sys	0m0.012s
 
null 1KB upload test 3 :
Traceback (most recent call last):
  File "FTclient.py", line 189, in <module>
    main()
  File "FTclient.py", line 164, in main
    server_socket.connect((HOST, PORT))
  File "/usr/local/Cellar/python/2.7.13/Frameworks/Python.framework/Versions/2.7/lib/python2.7/socket.py", line 228, in meth
    return getattr(self._sock,name)(*args)
socket.error: [Errno 61] Connection refused

real	0m0.054s
user	0m0.038s
sys	0m0.013s
 
null 1KB upload test 4 :
Traceback (most recent call last):
  File "FTclient.py", line 189, in <module>
    main()
  File "FTclient.py", line 164, in main
    server_socket.connect((HOST, PORT))
  File "/usr/local/Cellar/python/2.7.13/Frameworks/Python.framework/Versions/2.7/lib/python2.7/socket.py", line 228, in meth
    return getattr(self._sock,name)(*args)
socket.error: [Errno 61] Connection refused

real	0m0.052s
user	0m0.037s
sys	0m0.012s
 
null 1KB upload test 5 :
Traceback (most recent call last):
  File "FTclient.py", line 189, in <module>
    main()
  File "FTclient.py", line 164, in main
    server_socket.connect((HOST, PORT))
  File "/usr/local/Cellar/python/2.7.13/Frameworks/Python.framework/Versions/2.7/lib/python2.7/socket.py", line 228, in meth
    return getattr(self._sock,name)(*args)
socket.error: [Errno 61] Connection refused

real	0m0.052s
user	0m0.037s
sys	0m0.013s
 
null 1KB upload test 6 :
Traceback (most recent call last):
  File "FTclient.py", line 189, in <module>
    main()
  File "FTclient.py", line 164, in main
    server_socket.connect((HOST, PORT))
  File "/usr/local/Cellar/python/2.7.13/Frameworks/Python.framework/Versions/2.7/lib/python2.7/socket.py", line 228, in meth
    return getattr(self._sock,name)(*args)
socket.error: [Errno 61] Connection refused

real	0m0.052s
user	0m0.037s
sys	0m0.012s
 
null 1KB upload test 7 :
Traceback (most recent call last):
  File "FTclient.py", line 189, in <module>
    main()
  File "FTclient.py", line 164, in main
    server_socket.connect((HOST, PORT))
  File "/usr/local/Cellar/python/2.7.13/Frameworks/Python.framework/Versions/2.7/lib/python2.7/socket.py", line 228, in meth
    return getattr(self._sock,name)(*args)
socket.error: [Errno 61] Connection refused

real	0m0.052s
user	0m0.037s
sys	0m0.012s
 
null 1KB upload test 8 :
Traceback (most recent call last):
  File "FTclient.py", line 189, in <module>
    main()
  File "FTclient.py", line 164, in main
    server_socket.connect((HOST, PORT))
  File "/usr/local/Cellar/python/2.7.13/Frameworks/Python.framework/Versions/2.7/lib/python2.7/socket.py", line 228, in meth
    return getattr(self._sock,name)(*args)
socket.error: [Errno 61] Connection refused

real	0m0.052s
user	0m0.037s
sys	0m0.012s
 
null 1KB upload test 9 :
Traceback (most recent call last):
  File "FTclient.py", line 189, in <module>
    main()
  File "FTclient.py", line 164, in main
    server_socket.connect((HOST, PORT))
  File "/usr/local/Cellar/python/2.7.13/Frameworks/Python.framework/Versions/2.7/lib/python2.7/socket.py", line 228, in meth
    return getattr(self._sock,name)(*args)
socket.error: [Errno 61] Connection refused

real	0m0.054s
user	0m0.040s
sys	0m0.012s
 
null 1KB upload test 10 :
Traceback (most recent call last):
  File "FTclient.py", line 189, in <module>
    main()
  File "FTclient.py", line 164, in main
    server_socket.connect((HOST, PORT))
  File "/usr/local/Cellar/python/2.7.13/Frameworks/Python.framework/Versions/2.7/lib/python2.7/socket.py", line 228, in meth
    return getattr(self._sock,name)(*args)
socket.error: [Errno 61] Connection refused

real	0m0.052s
user	0m0.037s
sys	0m0.012s
 
null 1MB upload test 1 :
Traceback (most recent call last):
  File "FTclient.py", line 189, in <module>
    main()
  File "FTclient.py", line 164, in main
    server_socket.connect((HOST, PORT))
  File "/usr/local/Cellar/python/2.7.13/Frameworks/Python.framework/Versions/2.7/lib/python2.7/socket.py", line 228, in meth
    return getattr(self._sock,name)(*args)
socket.error: [Errno 61] Connection refused

real	0m0.058s
user	0m0.042s
sys	0m0.014s
 
null 1MB upload test 2 :
Traceback (most recent call last):
  File "FTclient.py", line 189, in <module>
    main()
  File "FTclient.py", line 164, in main
    server_socket.connect((HOST, PORT))
  File "/usr/local/Cellar/python/2.7.13/Frameworks/Python.framework/Versions/2.7/lib/python2.7/socket.py", line 228, in meth
    return getattr(self._sock,name)(*args)
socket.error: [Errno 61] Connection refused

real	0m0.062s
user	0m0.045s
sys	0m0.015s
 
null 1MB upload test 3 :
Traceback (most recent call last):
  File "FTclient.py", line 189, in <module>
    main()
  File "FTclient.py", line 164, in main
    server_socket.connect((HOST, PORT))
  File "/usr/local/Cellar/python/2.7.13/Frameworks/Python.framework/Versions/2.7/lib/python2.7/socket.py", line 228, in meth
    return getattr(self._sock,name)(*args)
socket.error: [Errno 61] Connection refused

real	0m0.053s
user	0m0.037s
sys	0m0.014s
 
null 1MB upload test 4 :
Traceback (most recent call last):
  File "FTclient.py", line 189, in <module>
    main()
  File "FTclient.py", line 164, in main
    server_socket.connect((HOST, PORT))
  File "/usr/local/Cellar/python/2.7.13/Frameworks/Python.framework/Versions/2.7/lib/python2.7/socket.py", line 228, in meth
    return getattr(self._sock,name)(*args)
socket.error: [Errno 61] Connection refused

real	0m0.052s
user	0m0.037s
sys	0m0.013s
 
null 1MB upload test 5 :
Traceback (most recent call last):
  File "FTclient.py", line 189, in <module>
    main()
  File "FTclient.py", line 164, in main
    server_socket.connect((HOST, PORT))
  File "/usr/local/Cellar/python/2.7.13/Frameworks/Python.framework/Versions/2.7/lib/python2.7/socket.py", line 228, in meth
    return getattr(self._sock,name)(*args)
socket.error: [Errno 61] Connection refused

real	0m0.054s
user	0m0.038s
sys	0m0.014s
 
null 1MB upload test 6 :
Traceback (most recent call last):
  File "FTclient.py", line 189, in <module>
    main()
  File "FTclient.py", line 164, in main
    server_socket.connect((HOST, PORT))
  File "/usr/local/Cellar/python/2.7.13/Frameworks/Python.framework/Versions/2.7/lib/python2.7/socket.py", line 228, in meth
    return getattr(self._sock,name)(*args)
socket.error: [Errno 61] Connection refused

real	0m0.051s
user	0m0.037s
sys	0m0.013s
 
null 1MB upload test 7 :
Traceback (most recent call last):
  File "FTclient.py", line 189, in <module>
    main()
  File "FTclient.py", line 164, in main
    server_socket.connect((HOST, PORT))
  File "/usr/local/Cellar/python/2.7.13/Frameworks/Python.framework/Versions/2.7/lib/python2.7/socket.py", line 228, in meth
    return getattr(self._sock,name)(*args)
socket.error: [Errno 61] Connection refused

real	0m0.057s
user	0m0.041s
sys	0m0.015s
 
null 1MB upload test 8 :
Traceback (most recent call last):
  File "FTclient.py", line 189, in <module>
    main()
  File "FTclient.py", line 164, in main
    server_socket.connect((HOST, PORT))
  File "/usr/local/Cellar/python/2.7.13/Frameworks/Python.framework/Versions/2.7/lib/python2.7/socket.py", line 228, in meth
    return getattr(self._sock,name)(*args)
socket.error: [Errno 61] Connection refused

real	0m0.053s
user	0m0.038s
sys	0m0.014s
 
null 1MB upload test 9 :
Traceback (most recent call last):
  File "FTclient.py", line 189, in <module>
    main()
  File "FTclient.py", line 164, in main
    server_socket.connect((HOST, PORT))
  File "/usr/local/Cellar/python/2.7.13/Frameworks/Python.framework/Versions/2.7/lib/python2.7/socket.py", line 228, in meth
    return getattr(self._sock,name)(*args)
socket.error: [Errno 61] Connection refused

real	0m0.053s
user	0m0.038s
sys	0m0.013s
 
null 1MB upload test 10 :
Traceback (most recent call last):
  File "FTclient.py", line 189, in <module>
    main()
  File "FTclient.py", line 164, in main
    server_socket.connect((HOST, PORT))
  File "/usr/local/Cellar/python/2.7.13/Frameworks/Python.framework/Versions/2.7/lib/python2.7/socket.py", line 228, in meth
    return getattr(self._sock,name)(*args)
socket.error: [Errno 61] Connection refused

real	0m0.053s
user	0m0.037s
sys	0m0.014s
 
null 1GB upload test 1 :
Traceback (most recent call last):
  File "FTclient.py", line 189, in <module>
    main()
  File "FTclient.py", line 164, in main
    server_socket.connect((HOST, PORT))
  File "/usr/local/Cellar/python/2.7.13/Frameworks/Python.framework/Versions/2.7/lib/python2.7/socket.py", line 228, in meth
    return getattr(self._sock,name)(*args)
socket.error: [Errno 61] Connection refused

real	0m0.051s
user	0m0.037s
sys	0m0.013s
 
null 1GB upload test 2 :
Traceback (most recent call last):
  File "FTclient.py", line 189, in <module>
    main()
  File "FTclient.py", line 164, in main
    server_socket.connect((HOST, PORT))
  File "/usr/local/Cellar/python/2.7.13/Frameworks/Python.framework/Versions/2.7/lib/python2.7/socket.py", line 228, in meth
    return getattr(self._sock,name)(*args)
socket.error: [Errno 61] Connection refused

real	0m0.052s
user	0m0.037s
sys	0m0.013s
 
null 1GB upload test 3 :
Traceback (most recent call last):
  File "FTclient.py", line 189, in <module>
    main()
  File "FTclient.py", line 164, in main
    server_socket.connect((HOST, PORT))
  File "/usr/local/Cellar/python/2.7.13/Frameworks/Python.framework/Versions/2.7/lib/python2.7/socket.py", line 228, in meth
    return getattr(self._sock,name)(*args)
socket.error: [Errno 61] Connection refused

real	0m0.052s
user	0m0.037s
sys	0m0.013s
 
null 1GB upload test 4 :
Traceback (most recent call last):
  File "FTclient.py", line 189, in <module>
    main()
  File "FTclient.py", line 164, in main
    server_socket.connect((HOST, PORT))
  File "/usr/local/Cellar/python/2.7.13/Frameworks/Python.framework/Versions/2.7/lib/python2.7/socket.py", line 228, in meth
    return getattr(self._sock,name)(*args)
socket.error: [Errno 61] Connection refused

real	0m0.053s
user	0m0.038s
sys	0m0.014s
 
null 1GB upload test 5 :
Traceback (most recent call last):
  File "FTclient.py", line 189, in <module>
    main()
  File "FTclient.py", line 164, in main
    server_socket.connect((HOST, PORT))
  File "/usr/local/Cellar/python/2.7.13/Frameworks/Python.framework/Versions/2.7/lib/python2.7/socket.py", line 228, in meth
    return getattr(self._sock,name)(*args)
socket.error: [Errno 61] Connection refused

real	0m0.052s
user	0m0.037s
sys	0m0.013s
 
null 1GB upload test 6 :
Traceback (most recent call last):
  File "FTclient.py", line 189, in <module>
    main()
  File "FTclient.py", line 164, in main
    server_socket.connect((HOST, PORT))
  File "/usr/local/Cellar/python/2.7.13/Frameworks/Python.framework/Versions/2.7/lib/python2.7/socket.py", line 228, in meth
    return getattr(self._sock,name)(*args)
socket.error: [Errno 61] Connection refused

real	0m0.055s
user	0m0.040s
sys	0m0.014s
 
null 1GB upload test 7 :
Traceback (most recent call last):
  File "FTclient.py", line 189, in <module>
    main()
  File "FTclient.py", line 164, in main
    server_socket.connect((HOST, PORT))
  File "/usr/local/Cellar/python/2.7.13/Frameworks/Python.framework/Versions/2.7/lib/python2.7/socket.py", line 228, in meth
    return getattr(self._sock,name)(*args)
socket.error: [Errno 61] Connection refused

real	0m0.053s
user	0m0.037s
sys	0m0.014s
 
null 1GB upload test 8 :
Traceback (most recent call last):
  File "FTclient.py", line 189, in <module>
    main()
  File "FTclient.py", line 164, in main
    server_socket.connect((HOST, PORT))
  File "/usr/local/Cellar/python/2.7.13/Frameworks/Python.framework/Versions/2.7/lib/python2.7/socket.py", line 228, in meth
    return getattr(self._sock,name)(*args)
socket.error: [Errno 61] Connection refused

real	0m0.052s
user	0m0.037s
sys	0m0.013s
 
null 1GB upload test 9 :
Traceback (most recent call last):
  File "FTclient.py", line 189, in <module>
    main()
  File "FTclient.py", line 164, in main
    server_socket.connect((HOST, PORT))
  File "/usr/local/Cellar/python/2.7.13/Frameworks/Python.framework/Versions/2.7/lib/python2.7/socket.py", line 228, in meth
    return getattr(self._sock,name)(*args)
socket.error: [Errno 61] Connection refused

real	0m0.052s
user	0m0.037s
sys	0m0.013s
 
null 1GB upload test 10 :
Traceback (most recent call last):
  File "FTclient.py", line 189, in <module>
    main()
  File "FTclient.py", line 164, in main
    server_socket.connect((HOST, PORT))
  File "/usr/local/Cellar/python/2.7.13/Frameworks/Python.framework/Versions/2.7/lib/python2.7/socket.py", line 228, in meth
    return getattr(self._sock,name)(*args)
socket.error: [Errno 61] Connection refused

real	0m0.057s
user	0m0.040s
sys	0m0.015s
